<?xml version="1.0" ?>
<robot name="zafeera_base" xmlns:xacro="http://www.ros.org/wiki/xacro">

<xacro:include filename="$(find zafeera_base_description)/urdf/materials.xacro" />
<xacro:include filename="$(find zafeera_base_description)/urdf/zafeera_base.trans" />
<xacro:include filename="$(find zafeera_base_description)/urdf/zafeera_base.gazebo" />
<link name="base_link">
  <inertial>
    <origin xyz="0.007907419808110348 0.00018804355094021247 0.04821740550091045" rpy="0 0 0"/>
    <mass value="0.800304200690207"/>
    <inertia ixx="0.009339" iyy="0.011731" izz="0.020943" ixy="-0.0" iyz="0.0" ixz="-6e-05"/>
  </inertial>
  <visual>
    <origin xyz="0 0 0" rpy="0 0 0"/>
    <geometry>
      <mesh filename="package://zafeera_base_description/meshes/base_link.stl" scale="0.001 0.001 0.001"/>
    </geometry>
    <material name="silver"/>
  </visual>
  <collision>
    <origin xyz="0 0 0" rpy="0 0 0"/>
    <geometry>
      <mesh filename="package://zafeera_base_description/meshes/base_link.stl" scale="0.001 0.001 0.001"/>
    </geometry>
  </collision>
</link>

<link name="left_wheel_1">
  <inertial>
    <origin xyz="4.214372445621867e-07 0.02249996737943144 6.938893903907228e-18" rpy="0 0 0"/>
    <mass value="0.3248024434720913"/>
    <inertia ixx="0.000256" iyy="0.000404" izz="0.000256" ixy="0.0" iyz="0.0" ixz="-0.0"/>
  </inertial>
  <visual>
    <origin xyz="-0.008753 -0.131083 -0.05" rpy="0 0 0"/>
    <geometry>
      <mesh filename="package://zafeera_base_description/meshes/left_wheel_1.stl" scale="0.001 0.001 0.001"/>
    </geometry>
    <material name="silver"/>
  </visual>
  <collision>
    <origin xyz="-0.008753 -0.131083 -0.05" rpy="0 0 0"/>
    <geometry>
      <mesh filename="package://zafeera_base_description/meshes/left_wheel_1.stl" scale="0.001 0.001 0.001"/>
    </geometry>
  </collision>
</link>

<link name="right_wheel_1">
  <inertial>
    <origin xyz="-5.032442903681045e-07 -0.02249961661343622 0.0" rpy="0 0 0"/>
    <mass value="0.3248024434720912"/>
    <inertia ixx="0.000256" iyy="0.000404" izz="0.000256" ixy="0.0" iyz="0.0" ixz="-0.0"/>
  </inertial>
  <visual>
    <origin xyz="-0.005146 0.130721 -0.05" rpy="0 0 0"/>
    <geometry>
      <mesh filename="package://zafeera_base_description/meshes/right_wheel_1.stl" scale="0.001 0.001 0.001"/>
    </geometry>
    <material name="silver"/>
  </visual>
  <collision>
    <origin xyz="-0.005146 0.130721 -0.05" rpy="0 0 0"/>
    <geometry>
      <mesh filename="package://zafeera_base_description/meshes/right_wheel_1.stl" scale="0.001 0.001 0.001"/>
    </geometry>
  </collision>
</link>

<link name="lidar_1">
  <inertial>
    <origin xyz="-2.750177009597232e-07 2.4523494977039535e-07 0.010015956854816294" rpy="0 0 0"/>
    <mass value="0.07282755266550214"/>
    <inertia ixx="1.9e-05" iyy="1.9e-05" izz="3.3e-05" ixy="-0.0" iyz="-0.0" ixz="-0.0"/>
  </inertial>
  <visual>
    <origin xyz="-0.120104 -0.000144 -0.074" rpy="0 0 0"/>
    <geometry>
      <mesh filename="package://zafeera_base_description/meshes/lidar_1.stl" scale="0.001 0.001 0.001"/>
    </geometry>
    <material name="silver"/>
  </visual>
  <collision>
    <origin xyz="-0.120104 -0.000144 -0.074" rpy="0 0 0"/>
    <geometry>
      <mesh filename="package://zafeera_base_description/meshes/lidar_1.stl" scale="0.001 0.001 0.001"/>
    </geometry>
  </collision>
</link>

<joint name="Revolute1" type="continuous">
  <origin xyz="0.008753 0.131083 0.05" rpy="0 0 0"/>
  <parent link="base_link"/>
  <child link="left_wheel_1"/>
  <axis xyz="1e-06 1.0 0.0"/>
</joint>

<joint name="Revolute2" type="continuous">
  <origin xyz="0.005146 -0.130721 0.05" rpy="0 0 0"/>
  <parent link="base_link"/>
  <child link="right_wheel_1"/>
  <axis xyz="1e-06 1.0 0.0"/>
</joint>

<joint name="Rigid3" type="fixed">
  <origin xyz="0.120104 0.000144 0.074" rpy="0 0 0"/>
  <parent link="base_link"/>
  <child link="lidar_1"/>
</joint>

</robot>
